Workbook

Sheet >> Execution

Sheet 📍Bảng confirm EXT - 2404 Quota
A1: PMAX | C.P.GROUP VIETNAM - QUOTATION FOR INFLUENCERS BOOKING SERVICE
A3: No | B3: Booking | C3: Unit | D3: Outcomes Quantity | E3: Total Cost
C4: KOL & Community | D4: =sum(D5,D7,D9:D10) -> 37 | E4: =Sum(E5:E11) -> 616000000
A5: 1 | B5: =A20 -> FOODY REVIEWER | C5: Video Post | D5: =K20 -> 9 | E5: =Q20 -> 217000000
C6: SDHA | D6: =K21 -> 9
A7: 2 | B7: =A50 -> FOODY UGC | C7: Video Post | D7: =K50 -> 18 | E7: =Q50 -> 163000000
C8: SDHA | D8: =K51 -> 18
A9: 3 | B9: =A114 -> FOODY COMMUNITY | C9: Video Post | D9: =K115 -> 5 | E9: =Q114 -> 216000000
C10: Photo Post | D10: =K114 -> 5
A11: 4 | B11: =A126 -> SEEDING PACKAGE | C11: Comment | D11: =K127 -> 2000 | E11: =Q126 -> 20000000
B12: Total (exl AF, exl VAT) | E12: =E4 -> 616000000
B13: AF | D13: 0.12 | E13: =E12*D13 -> 73920000
B14: Total (inc AF, exl VAT) | E14: =sum(E12:E13) -> 689920000
B15: Total (inc AF, VAT) | E15: =E14*1.08 -> 745113600
A19: No. | B19: Name | C19: Platform | D19: Followers | E19: Tiers | F19: Link | G19: Location | H19: SOW | I19: Pick | J19: Unit | K19: Outcomes Quantity | L19: Unit cost ( Estimated) | M19: KPI View | N19: KPI Engagement | O19: CPV | P19: CPE | Q19: Total cost | R19: Rationale | S19: NOTE | T19: PMAX' NOTE | U19: Vote
A20: FOODY REVIEWER | J20: Video Post | K20: =SUMIFS(K22:K49,J22:J49,"Video Post") -> 9 | M20: =sumif($I$22:$I$49,"TRUE",M22:M49) -> 710000 | N20: =sumif($I$22:$I$49,"TRUE",N22:N49) -> 28700 | Q20: =sum(Q22:Q49) -> 217000000
J21: SDHA | K21: =SUMIFS(K22:K49,J22:J49,"Tháng") -> 9
A22: Confirmed | B22: Thắng Lợi | C22: Tiktok | D22: 426.5K | E22: Micro | F22: Link | G22: Đồng Nai | H22: Sản xuất và đăng tải 01 Tiktok Video Review sản phẩm tại điểm bán Five Star Kiosk, theo định hướng nội dung của nhãn hàng - Thời lượng: 60-120s - Chất lượng: phù hợp điện thoại - Địa điểm: tại các Five Star Kiosk ở Tp. HCM Map Five Star Kiosk: Link | I22: TRUE | J22: Video Post | K22: =if(I22=True,1,if(I22=False,0)) -> 1 | L22: 16000000 | M22: 50000 | N22: 3000 | O22: =IFERROR(Q22/M22,"-") -> 320 | P22: =IFERROR(Q22/N22,"-") -> 5333.3333 | Q22: =iferror(L22*K22,"-") -> 16000000 | R22: Giới thiệu Profile Food/lifestyle reviewer có quy mô khá lớn; Tệp khán giả đại chúng, thiên về người trẻ xem TikTok để tìm quán, tìm món, tìm địa điểm vui cuối tuần; phù hợp cho nhóm người xem cần nội dung nhanh, dễ hiểu, quyết định thử món nhanh. Lý do phù hợp Đây là gương mặt phù hợp cho mục tiêu độ phủ. Với nền tảng follower/like lớn, Thắng Lợi có khả năng giúp Fivestar review món gà rán theo kiểu mass-friendly, dễ viral, dễ kéo reach; đồng thời vẫn bám đúng territory ăn uống/quán xá. | S22: Review khá đa dạng, từ các nhà hàng cao cấp đến các món nướng vỉa hè -> audience target khá dàn trải ER cao (6%) | U22: Confirm
H23: 01 tháng Sử dụng hình ảnh không độc quyền trên digital only *Bao gồm: Code Ads và reup kênh brand có chạy quảng cáo | I23: TRUE | J23: Tháng | K23: =if(I23=True,1,if(I23=False,0)) -> 1 | L23: 8000000 | M23: 0 | N23: 0 | O23: =IFERROR(Q23/M23,"-") -> - | P23: =IFERROR(Q23/N23,"-") -> - | Q23: =iferror(L23*K23,"-") -> 8000000
A24: Confirmed | B24: Lulu Review | C24: Tiktok | D24: 336.4K | E24: Micro | F24: Link | G24: Hồ Chí Minh | H24: Sản xuất và đăng tải 01 Tiktok Video Review sản phẩm tại điểm bán Five Star Kiosk, theo định hướng nội dung của nhãn hàng - Thời lượng: 60-120s - Chất lượng: phù hợp điện thoại - Địa điểm: tại các Five Star Kiosk ở Tp. HCM Map Five Star Kiosk: Link | I24: TRUE | J24: Video Post | K24: =if(I24=True,1,if(I24=False,0)) -> 1 | L24: 12000000 | M24: 100000 | N24: 3000 | O24: =IFERROR(Q24/M24,"-") -> 120 | P24: =IFERROR(Q24/N24,"-") -> 4000 | Q24: =iferror(L24*K24,"-") -> 12000000 | R24: Giới thiệu Profile Creator thiên về travel – food, creator làm các clip trải nghiệm ăn uống/điểm đến. Khán giả thích kết hợp ăn uống + đi chơi + khám phá địa điểm, thiên về nhóm trẻ thích lifestyle/travel nội địa. Audience này phù hợp với Fivestar khi thương hiệu muốn mở rộng từ “món ăn” sang “điểm chạm trong hành trình vui chơi” Lý do phù hợp Lulu phù hợp để kể Fivestar theo góc đi đâu ăn đó / tiện ghé – tiện trải nghiệm, không chỉ review món gà rán mà còn gắn với hành trình đi chơi, đi ăn, check-in. Điều này hợp với các hoạt động activation hoặc ghé cửa hàng trong hành trình khám phá thành phố | S24: Review khá đa dạng các lĩnh vực -> audience target khá dàn trải | U24: Confirm
H25: 01 tháng Sử dụng hình ảnh không độc quyền trên digital only *Bao gồm: Code Ads và reup kênh brand có chạy quảng cáo | I25: TRUE | J25: Tháng | K25: =if(I25=True,1,if(I25=False,0)) -> 1 | L25: 6000000 | M25: 0 | N25: 0 | O25: =IFERROR(Q25/M25,"-") -> - | P25: =IFERROR(Q25/N25,"-") -> - | Q25: =iferror(L25*K25,"-") -> 6000000
A26: Confirmed | B26: Hello Lập Đây | C26: Tiktok | D26: 260K | E26: Micro | F26: Link | G26: Hồ Chí Minh | H26: Sản xuất và đăng tải 01 Tiktok Video Review sản phẩm tại điểm bán Five Star Kiosk, theo định hướng nội dung của nhãn hàng - Thời lượng: 60-120s - Chất lượng: phù hợp điện thoại - Địa điểm: tại các Five Star Kiosk ở Tp. HCM Map Five Star Kiosk: Link | I26: TRUE | J26: Video Post | K26: =if(I26=True,1,if(I26=False,0)) -> 1 | L26: 20000000 | M26: 130000 | N26: 4000 | O26: =IFERROR(Q26/M26,"-") -> 153.84615 | P26: =IFERROR(Q26/N26,"-") -> 5000 | Q26: =iferror(L26*K26,"-") -> 20000000 | R26: Giới thiệu Profile Creator về du lịch và đời sống, ăn uống , đồng thời Lập cũng nói rõ mình “thích ăn ngon thích trải nghiệm”. Khán giả trẻ yêu thích trải nghiệm đời sống, du lịch ngắn ngày, quán xá và những nội dung nhẹ nhàng dễ xem; phù hợp với nhóm người xem thích recommendation kiểu “đi đâu – ăn gì – chơi gì” Lý do phù hợp Lập không phải pure foodie 100%, nhưng lại rất hợp cho tuyến review trải nghiệm thương hiệu: ghé cửa hàng, ăn thử món, tham gia hoạt động brand, kể cảm xúc theo kiểu gần gũi và vui vẻ. Đây là kiểu creator giúp Fivestar không chỉ bán món mà còn bán trải nghiệm ghé ăn – đi chơi – thư giãn. | S26: Tuyến content dàn trải nhưng khá tự nhiên | U26: Confirm
H27: 01 tháng Sử dụng hình ảnh không độc quyền trên digital only *Bao gồm: Code Ads và reup kênh brand có chạy quảng cáo | I27: TRUE | J27: Tháng | K27: =if(I27=True,1,if(I27=False,0)) -> 1 | L27: 13000000 | M27: 0 | N27: 0 | O27: =IFERROR(Q27/M27,"-") -> - | P27: =IFERROR(Q27/N27,"-") -> - | Q27: =iferror(L27*K27,"-") -> 13000000
A28: Confirmed | B28: Huyền Nhi | C28: Tiktok | D28: 118.1K | E28: Micro | F28: Link | G28: Hồ Chí Minh | H28: Sản xuất và đăng tải 01 Tiktok Video Review sản phẩm tại điểm bán Five Star Kiosk, theo định hướng nội dung của nhãn hàng - Thời lượng: 60-120s - Chất lượng: phù hợp điện thoại - Địa điểm: tại các Five Star Kiosk ở Tp. HCM Map Five Star Kiosk: Link | I28: TRUE | J28: Video Post | K28: =if(I28=True,1,if(I28=False,0)) -> 1 | L28: 8000000 | M28: 30000 | N28: 1200 | O28: =IFERROR(Q28/M28,"-") -> 266.66667 | P28: =IFERROR(Q28/N28,"-") -> 6666.6667 | Q28: =iferror(L28*K28,"-") -> 8000000 | R28: Giới thiệu Profile Creator thiên về food/lifestyle ở quy mô nhỏ hơn, cũng như từng đăng nội dung liên quan KFC tầm 1 năm trước. Tệp người xem trẻ, thiên nữ, quan tâm quán xá đẹp, món ngon dễ hẹn bạn bè hoặc đi hẹn hò; phù hợp cho nhóm cần cảm hứng “thấy hợp là đi thử”. Lý do phù hợp Huyền Nhi phù hợp cho tuyến micro/nano KOC nếu brand cần cảm giác review thật, mềm, nữ tính và gần gũi. Creator này hợp với các nội dung thử món, đi ăn cùng bạn bè, hoặc review cửa hàng theo vibe nhẹ nhàng, dễ tin. | S28: ER ổn (4) Giá phù hợp với KPI Nội dung ẩm thực là chính | U28: Confirm
H29: 01 tháng Sử dụng hình ảnh không độc quyền trên digital only *Bao gồm: Code Ads và reup kênh brand có chạy quảng cáo | I29: TRUE | J29: Tháng | K29: =if(I29=True,1,if(I29=False,0)) -> 1 | L29: 4000000 | M29: 0 | N29: 0 | O29: =IFERROR(Q29/M29,"-") -> - | P29: =IFERROR(Q29/N29,"-") -> - | Q29: =iferror(L29*K29,"-") -> 4000000
A30: Confirmed | B30: Thư Bonny | C30: Tiktok | D30: 114.7K | E30: Micro | F30: Link | G30: Hồ Chí Minh | H30: Sản xuất và đăng tải 01 Tiktok Video Review sản phẩm tại điểm bán Five Star Kiosk, theo định hướng nội dung của nhãn hàng - Thời lượng: 60-120s - Chất lượng: phù hợp điện thoại - Địa điểm: tại các Five Star Kiosk ở Tp. HCM Map Five Star Kiosk: Link | I30: TRUE | J30: Video Post | K30: =if(I30=True,1,if(I30=False,0)) -> 1 | L30: 10000000 | M30: 50000 | N30: 3000 | O30: =IFERROR(Q30/M30,"-") -> 200 | P30: =IFERROR(Q30/N30,"-") -> 3333.3333 | Q30: =iferror(L30*K30,"-") -> 10000000 | R30: Giới thiệu Profile Creator quy mô nhỏ, nội dung xoay quanh food review tại Sài Gòn như hủ tiếu Nam Vang, món mới, quán ăn. Tệp khán giả địa phương quan tâm quán ăn Sài Gòn và các gợi ý món ăn thường ngày; phù hợp cho mục tiêu phủ thêm lớp recommendation thực tế ở nhóm niche audience. Lý do phù hợp Thư Bonny hợp cho tuyến nano KOC seeding hơn là lead KOL. Điểm cộng là cảm giác gần gũi, ít “quảng cáo hóa”, phù hợp nếu Fivestar muốn có thêm lớp nội dung review chân thật, đời thường, dễ tạo niềm tin ở nhóm người xem nhỏ nhưng sát nhu cầu ăn uống hàng ngày. | S30: ER cao KPI ok Review khá đa dạng | U30: Confirm
H31: 01 tháng Sử dụng hình ảnh không độc quyền trên digital only *Bao gồm: Code Ads và reup kênh brand có chạy quảng cáo | I31: TRUE | J31: Tháng | K31: =if(I31=True,1,if(I31=False,0)) -> 1 | L31: 5000000 | M31: 0 | N31: 0 | O31: =IFERROR(Q31/M31,"-") -> - | P31: =IFERROR(Q31/N31,"-") -> - | Q31: =iferror(L31*K31,"-") -> 5000000
A32: Considering | B32: Nuchuu nè | C32: Tiktok | D32: 756K | E32: Micro | F32: Link | G32: Hồ Chí Minh | H32: Sản xuất và đăng tải 01 Tiktok Video Review sản phẩm tại điểm bán Five Star Kiosk, theo định hướng nội dung của nhãn hàng - Thời lượng: 60-120s - Chất lượng: phù hợp điện thoại - Địa điểm: tại các Five Star Kiosk ở Tp. HCM Map Five Star Kiosk: Link | I32: TRUE | J32: Video Post | K32: =if(I32=True,1,if(I32=False,0)) -> 1 | L32: 30000000 | M32: 120000 | N32: 4500 | O32: =IFERROR(Q32/M32,"-") -> 250 | P32: =IFERROR(Q32/N32,"-") -> 6666.6667 | Q32: =iferror(L32*K32,"-") -> 30000000 | R32: Giới thiệu Profile Food reviewer theo hướng gần gũi, hay làm format “cầm 100 cành ăn sập…” và review quán/điểm ăn uống thực tế; phần mô tả YouTube cũng cho thấy Nuchuu chia sẻ công thức nấu ăn và “review thật lòng” về thực phẩm, quán ăn. Kênh thu hút nhóm khán giả trẻ thích săn quán, thích nội dung ăn uống đời thường, ưu tiên món ngon dễ thử, dễ rủ hội bạn đi cùng; phù hợp với tệp Gen Z–young millennials mê khám phá địa điểm ăn uống phổ thông. Lý do phù hợp Nuchuu hợp để review gà rán theo góc độ “ngon thật – dễ ăn – dễ chốt kèo” vì nội dung thiên về trải nghiệm thật, món ăn phổ thông, dễ tạo cảm giác thèm ăn ngay. Format săn món ngon giá hợp lý cũng match với tinh thần tiếp cận rộng, tiện ăn, tiện rủ bạn bè của Fivestar. | S32: Có review quán ăn vặt của chủ kênh vào 23/1 (có món gà) | T32: PMAX Updated KPI | U32: Confirm
H33: 01 tháng Sử dụng hình ảnh không độc quyền trên digital only *Bao gồm: Code Ads và reup kênh brand có chạy quảng cáo | I33: TRUE | J33: Tháng | K33: =if(I33=True,1,if(I33=False,0)) -> 1 | L33: 17000000 | M33: 0 | N33: 0 | O33: - | P33: - | Q33: =iferror(L33*K33,"-") -> 17000000
A34: Considering | B34: Lên ký Cùng Khoa | C34: Tiktok | D34: 726.4K | E34: Micro | F34: Link | G34: Hồ Chí Minh | H34: Sản xuất và đăng tải 01 Tiktok Video Review sản phẩm tại điểm bán Five Star Kiosk, theo định hướng nội dung của nhãn hàng - Thời lượng: 60-120s - Chất lượng: phù hợp điện thoại - Địa điểm: tại các Five Star Kiosk ở Tp. HCM Map Five Star Kiosk: Link | I34: FALSE | J34: Video Post | K34: =if(I34=True,1,if(I34=False,0)) -> 0 | L34: 22000000 | M34: 100000 | N34: 3500 | O34: =IFERROR(Q34/M34,"-") -> 0 | P34: =IFERROR(Q34/N34,"-") -> 0 | Q34: =iferror(L34*K34,"-") -> 0 | R34: Giới thiệu Profile Creator food khá rõ nét, kênh chính chủ mô tả là nơi xem “review mới nhất”; trên YouTube có các tuyến nội dung như review quán ăn Sài Gòn, review hot trend, món miền Tây, công thức của mẹ. Tệp người xem thích cập nhật quán hot, món hot trend, món ăn đường phố/quen thuộc; phù hợp với khán giả trẻ thích thử món mới nhưng vẫn ưu tiên trải nghiệm dễ tiếp cận, giá không quá cao. Lý do phù hợp Khoa phù hợp để kéo review món + review điểm bán + bắt trend món mới. Nội dung kênh vừa có tính khám phá vừa có độ “đời”, nên dễ kể câu chuyện Fivestar không chỉ là gà rán mà còn là điểm dừng chân ăn nhanh, ngon, dễ ghé. | S34: ER hơi thấp (2%), cost per engagement cao | T34: PMAX Updated KPI | U34: Không phù hợp
H35: 01 tháng Sử dụng hình ảnh không độc quyền trên digital only *Bao gồm: Code Ads và reup kênh brand có chạy quảng cáo | I35: FALSE | J35: Tháng | K35: =if(I35=True,1,if(I35=False,0)) -> 0 | L35: 13000000 | M35: 0 | N35: 0 | O35: =IFERROR(Q35/M35,"-") -> - | P35: =IFERROR(Q35/N35,"-") -> - | Q35: =iferror(L35*K35,"-") -> 0
A36: Considering | B36: Ăn ngon cùng Puu | C36: Tiktok | D36: 345.4K | E36: Micro | F36: Link | G36: Hồ Chí Minh | H36: Sản xuất và đăng tải 01 Tiktok Video Review sản phẩm tại điểm bán Five Star Kiosk, theo định hướng nội dung của nhãn hàng - Thời lượng: 60-120s - Chất lượng: phù hợp điện thoại - Địa điểm: tại các Five Star Kiosk ở Tp. HCM Map Five Star Kiosk: Link | I36: TRUE | J36: Video Post | K36: =if(I36=True,1,if(I36=False,0)) -> 1 | L36: 17000000 | M36: 100000 | N36: 4000 | O36: =IFERROR(Q36/M36,"-") -> 170 | P36: =IFERROR(Q36/N36,"-") -> 4250 | Q36: =iferror(L36*K36,"-") -> 17000000 | R36: Giới thiệu Profile Kênh food review; Tệp người xem chủ động tìm nội dung ăn uống, ưu tiên recommendation nhanh về món/quán; phù hợp với nhóm khán giả trẻ mê food content, dễ bị tác động bởi visual món ăn và reaction khi ăn Lý do phù hợp Puu phù hợp với tuyến review món ăn trực diện, tập trung vào cảm nhận vị, độ hấp dẫn và trải nghiệm ăn thực tế. Với tên kênh và định vị khá rõ là “ăn ngon”, creator này match tốt với brief cần làm người xem thèm món ngay khi xem | S36: KPI View cao ER hơi thấp (2,67%) | T36: PMAX Updated KPI | U36: Confirm
H37: 01 tháng Sử dụng hình ảnh không độc quyền trên digital only *Bao gồm: Code Ads và reup kênh brand có chạy quảng cáo | I37: TRUE | J37: Tháng | K37: =if(I37=True,1,if(I37=False,0)) -> 1 | L37: 7000000 | M37: 0 | N37: 0 | O37: =IFERROR(Q37/M37,"-") -> - | P37: =IFERROR(Q37/N37,"-") -> - | Q37: =iferror(L37*K37,"-") -> 7000000
A38: Considering | B38: Thồn | C38: Tiktok | D38: 197.2K | E38: Micro | F38: Link | G38: Hồ Chí Minh | H38: Sản xuất và đăng tải 01 Tiktok Video Review sản phẩm tại điểm bán Five Star Kiosk, theo định hướng nội dung của nhãn hàng - Thời lượng: 60-120s - Chất lượng: phù hợp điện thoại - Địa điểm: tại các Five Star Kiosk ở Tp. HCM Map Five Star Kiosk: Link | I38: FALSE | J38: Video Post | K38: =if(I38=True,1,if(I38=False,0)) -> 0 | L38: 17000000 | M38: 60000 | N38: 2500 | O38: =IFERROR(Q38/M38,"-") -> 0 | P38: =IFERROR(Q38/N38,"-") -> 0 | Q38: =iferror(L38*K38,"-") -> 0 | R38: Giới thiệu Profile Creator food/travel có cá tính rõ, . Nhóm khán giả thích food content có cá tính, vừa xem để lấy gợi ý quán/món vừa xem vì persona creator thú vị; phù hợp với tệp trẻ thành thị thích nội dung review vui, dễ nhớ, có chút giải trí. Lý do phù hợp Điểm mạnh của Thồn là persona nhớ mặt nhớ giọng, tạo cảm giác review có màu riêng, không bị nhạt. Với Fivestar, creator này có thể làm nội dung gà rán theo hướng thử thật – reaction thật – kể chuyện có nét riêng, tăng độ ghi nhớ thương hiệu hơn kiểu review thông tin thuần túy | S38: ER cao nhưng KPI Engagement khá thấp ( chỉ 2000) -> đẩy cost per E lên cao Review khá đa dạng, | T38: PMAX Updated KPI | U38: Không phù hợp
H39: 01 tháng Sử dụng hình ảnh không độc quyền trên digital only *Bao gồm: Code Ads và reup kênh brand có chạy quảng cáo | I39: FALSE | J39: Tháng | K39: =if(I39=True,1,if(I39=False,0)) -> 0 | L39: 10000000 | M39: 0 | N39: 0 | O39: =IFERROR(Q39/M39,"-") -> - | P39: =IFERROR(Q39/N39,"-") -> - | Q39: =iferror(L39*K39,"-") -> 0
A40: New Propose | B40: Đi Ăn Chưa 🍪 | C40: Tiktok | D40: 289.3K | E40: Micro | F40: https://www.tiktok.com/@bobiengan?_t=ZS-8tu0m1Vyokq&_r=1u0odLK9R3&_r=1 | G40: Hà Nội | H40: Sản xuất và đăng tải 01 Tiktok Video Review sản phẩm tại điểm bán Five Star Kiosk, theo định hướng nội dung của nhãn hàng - Thời lượng: 60-120s - Chất lượng: phù hợp điện thoại - Địa điểm: tại các Five Star Kiosk ở Tp. HCM Map Five Star Kiosk: Link | I40: TRUE | J40: Video Post | K40: =if(I40=True,1,if(I40=False,0)) -> 1 | L40: 15000000 | M40: 65000 | N40: 3000 | O40: =IFERROR(Q40/M40,"-") -> 230.76923 | P40: =IFERROR(Q40/N40,"-") -> 5000 | Q40: =iferror(L40*K40,"-") -> 15000000 | R40: Giới thiệu Profile Kênh food review có định vị rõ về ăn uống, dễ tạo cảm giác rủ rê và kích thích người xem đi ăn ngay. Tên kênh mang tính call-to-action tự nhiên, phù hợp với nhóm khán giả chủ động tìm recommendation món/quán, thích nội dung review nhanh, visual ngon mắt và reaction thực tế. Lý do phù hợp Đi Ăn Chưa phù hợp để truyền tải Fivestar như một lựa chọn ăn uống tiện, ngon và dễ chốt kèo. Tinh thần “đi ăn chưa” match tốt với thông điệp rủ bạn bè cùng ăn gà rán, giúp nội dung brand trở nên tự nhiên, gần gũi và có khả năng kích thích hành động thử món. | U40: Confirm
H41: 01 tháng Sử dụng hình ảnh không độc quyền trên digital only *Bao gồm: Code Ads và reup kênh brand có chạy quảng cáo | I41: TRUE | J41: Tháng | K41: =if(I41=True,1,if(I41=False,0)) -> 1 | L41: 4000000 | M41: 0 | N41: 0 | O41: =IFERROR(Q41/M41,"-") -> - | P41: =IFERROR(Q41/N41,"-") -> - | Q41: =iferror(L41*K41,"-") -> 4000000
A42: Brand Propose | B42: A dinosaur in the kitchen | C42: Tiktok | D42: 294.8K | E42: Micro | F42: https://www.tiktok.com/@phamtrang.2401 | G42: Hà Nội | H42: Sản xuất và đăng tải 01 Tiktok Video Review sản phẩm tại điểm bán Five Star Kiosk, theo định hướng nội dung của nhãn hàng - Thời lượng: 60-120s - Chất lượng: phù hợp điện thoại - Địa điểm: tại các Five Star Kiosk ở Tp. HCM Map Five Star Kiosk: Link | I42: TRUE | J42: Video Post | K42: =if(I42=True,1,if(I42=False,0)) -> 1 | L42: 19000000 | M42: 65000 | N42: 3000 | O42: =IFERROR(Q42/M42,"-") -> 292.30769 | P42: =IFERROR(Q42/N42,"-") -> 6333.3333 | Q42: =iferror(L42*K42,"-") -> 19000000 | R42: Giới thiệu Profile Creator lifestyle/food nhẹ nhàng, nội dung mang tính daily life, trải nghiệm đa dạng món ăn Phong cách quay đẹp, nội dung lôi cuốn người xe và có tệp người xem thích vibe chill, nội dung dễ xem – dễ áp dụng. Lý do phù hợp Phù hợp lồng ghép Fivestar vào context ăn uống hằng ngày . Tăng cảm giác thương hiệu gần gũi, dễ trở thành lựa chọn quen thuộc. | U42: Confirm
H43: 01 tháng Sử dụng hình ảnh không độc quyền trên digital only *Bao gồm: Code Ads và reup kênh brand có chạy quảng cáo | I43: TRUE | J43: Tháng | K43: =if(I43=True,1,if(I43=False,0)) -> 1 | L43: 6000000 | M43: 0 | N43: 0 | O43: =IFERROR(Q43/M43,"-") -> - | P43: =IFERROR(Q43/N43,"-") -> - | Q43: =iferror(L43*K43,"-") -> 6000000
A44: Brand Propose | B44: Ăn Sập Hà Nội | C44: Tiktok | D44: 1.5M | E44: Macro | F44: https://www.tiktok.com/@ansaphanoi | G44: Hà Nội | H44: Sản xuất và đăng tải 01 Tiktok Video Review sản phẩm tại điểm bán Five Star Kiosk, theo định hướng nội dung của nhãn hàng - Thời lượng: 60-120s - Chất lượng: phù hợp điện thoại - Địa điểm: tại các Five Star Kiosk ở Tp. HCM Map Five Star Kiosk: Link | I44: FALSE | J44: Video Post | K44: =if(I44=True,1,if(I44=False,0)) -> 0 | L44: 0 | M44: 0 | N44: 0 | O44: =IFERROR(Q44/M44,"-") -> - | P44: =IFERROR(Q44/N44,"-") -> - | Q44: =iferror(L44*K44,"-") -> 0 | S44: KOC không nhận job | U44: Đề xuất thêm
...

Sheet INT | Influencer Execution Trac
A1: PMAX | C.P.GROUP VIETNAM - INFLUENCERS WORKPLAN | H1: XM | J1: Meci | N1: T5A
J2: =counta(J5:J970) &"/37" -> 38/37 | K2: =counta(K5:K970) &"/37" -> 0/37 | L2: =counta(L5:L970) &"/37" -> 0/37 | M2: =counta(M5:M970) &"/37" -> 35/37 | N2: =counta(N5:N970) &"/37" -> 37/37 | O2: =counta(O5:O970) &"/37" -> 7/37 | P2: =counta(P5:P970) &"/37" -> 36/37 | Q2: =counta(Q5:Q970) &"/37" -> 35/37 | ... S2: =counta(S5:S970) &"/37" -> 36/37 | U2: =counta(U4:U970) &"/37" -> 37/37 | V2: =counta(V5:V970) &"/37" -> 3/37 | W2: =counta(W4:W970) &"/37" -> 37/37 | X2: =counta(X4:X970) &"/37" -> 37/37 | Y2: =counta(Y5:Y970) &"/37" -> 4/37 | Z2: =counta(Z4:Z970) &"/37" -> 35/37 | AA2: =counta(AA4:AA970) &"/37" -> 31/37 | AB2: =counta(AB5:AB970) &"/37" -> 30/37 | AD2: =counta(AD4:AD970) &"/37" -> 37/37 | AE2: =counta(AE4:AE970) &"/37" -> 27/37 | AF2: =counta(AF4:AF970) &"/37" -> 11/37 | AG2: =counta(AG6:AG970) &"/37" -> 36/37 | AH2: =counta(AH4:AH970) &"/37" -> 18/37
A3: No. | B3: Influencer | C3: Platform | D3: Followers | E3: Tiers | F3: Link | G3: Location | H3: SOW | I3: Outfit Tracking | J3: Địa điểm quay + thời gian | K3: Outfit | L3: Outfit | M3: Tình trạng | N3: SCRIPT R1 | O3: Feedback PMAX R1 | P3: Feedback Brand team R1 | Q3: SCRIPT R2 | R3: Feedback PMAX R2 | S3: Feedback Brand team R2 | U3: DEMO R1 | V3: Feedback PMAX R1 | W3: Feedback Brand team R1 | X3: DEMO R2 | Y3: Feedback PMAX R2 | Z3: Feedback Brand team R2 | AA3: Final Demo | AB3: Status | AC3: Final Demo Revise | AD3: Caption | AE3: Feedbacks caption | AF3: Caption Revised | AG3: Lịch Air dự kiến | AH3: LINK AIR | AI3: GHI CHÚ
A4: FOODY REVIEWER
A5: 1 | B5: Thắng Lợi | C5: Tiktok | D5: 426.5K | E5: Micro | F5: Link | G5: Đồng Nai | H5: Sản xuất và đăng tải 01 Tiktok Video Review sản phẩm tại điểm bán Five Star Kiosk, theo định hướng nội dung của nhãn hàng - Thời lượng: 60-120s - Chất lượng: phù hợp điện thoại - Địa điểm: tại các Five Star Kiosk ở nơi sinh sống Map Five Star Kiosk: Link 01 tháng Sử dụng hình ảnh không độc quyền trên digital only *Bao gồm: Code Ads và reup kênh brand có chạy quảng cáo | I5: FALSE | J5: 13/5 19h00 BASIC SHOP - Nguyễn Thị Thuận - Số 67 Đường 9, phường Trường Thọ, TP. Thủ Đức, TP. HCM | M5: Đã quay | N5: =Draft!M5 -> https://docs.google.com/spreadsheets/d/1sek28q8dSpx6DU8QYhlKU5FqtCePEZaUhxd1o63zgyI/edit?gid=1935125103#gid=1935125103 | O5: =Draft!N5 | P5: - Câu hook đầu tiên có thể gắn thêm context rõ ràng để tạo sự quen thuộc > ví dụ: có những hôm trời mưa lạnh lạnh bụng thì đói mà không đi đâu xa được, đang đi trên đường mà bụng đói,v.v. - “Chỗ cứu đói cực nhanh” hiện còn khá generic, vì brand fastfood nào cũng có thể nói vậy. Có thể bổ sung chi tiết về kiosk Five Star nổi bật hoặc độ phủ quen thuộc ở nhiều góc phố để tạo cảm giác gần gũi. - Phần review món ăn hiện tại hơi flat > có thể thêm reaction, thêm chi tiết về món ăn (hương vị, độ giòn,v.v.) để tạo sự hấp dẫn - CTA chưa đủ mạnh, có thể thay bằng “Món nào ở Five Star mọi người thấy underrated nhất?”; “Ai giống mình, đi ngang chỉ định mua 1 món nhưng cuối cùng cầm nguyên bịch?”; “Có ai ban đầu không kỳ vọng nhiều nhưng ăn rồi bị ghiền không?” - Gắn thêm địa chỉ về địa điểm Five Star mà bạn đã ghé | Q5: https://docs.google.com/spreadsheets/d/1sek28q8dSpx6DU8QYhlKU5FqtCePEZaUhxd1o63zgyI/edit?gid=771502114#gid=771502114 | R5: Đã update script và Outfit chờ team check | S5: Remove từ kiosk Còn lại ok | U5: https://drive.google.com/drive/folders/15ODXPBRTw5WmN8MAY5ueU-3G_tHaar-8 | V5: =Draft!U5 | W5: 0:04 Bỏ địa chỉ, thời gian 0:20 - Mention tên các món xiên que đặc biệt thay vì chỉ nói bò viên cá viên - Xúc xích toperdo, chả giò gai jor, gà nugget Cho màu món ăn tươi hơn, tăng saturation, sáng hơn | X5: https://drive.google.com/file/d/1W_rLKrdvJSUqVmyRZnA2Vx3-PkXcG-_A/view?usp=drive_link | Y5: =Draft!X5 | Z5: chỉnh text giá tham khảo rẻ > giá hợp lý 1:01 - Five Star chi nhánh .. ghi địa chỉ, bỏ basic shop Add cta kêu gọi ghé five star gần nhà Leo's comment: 0:28: Gà miếng nhưng text là "gà nugget" => Sai tên sản phẩm, sửa thành "gà giòn giòn" 0:31: "Gà không bị khô đâu" nhưng cảnh xé gá hơi lâu => Cắt ngắn cảnh xé gà lại 0:35: Bỏ text "bò viên, cá viên" đổi thành "chả cá hàn quốc, chả giò gai jor thái lan" 0:41: Bỏ text "xúc xích toperdo, chả giò gai jor" đổi thành "xúc xích sumo, gà nugget, gà popcorn" | AA5: https://drive.google.com/file/d/1h74wlhoDoRD_Y03lKWFQV6RdRRRdzK7N/view?usp=drivesdk | AB5: Confirm | AD5: Nếu hnay bạn phân vân ăn gì thử có thể cân nhắc Fivestar nhé #FiveStarVietnam #GaDau | AG5: 46087 | AH5: https://vt.tiktok.com/ZSQ1XDNsR/
A6: 2 | B6: Lulu Review | C6: Tiktok | D6: 336.4K | E6: Micro | F6: Link | G6: Hồ Chí Minh | H6: Sản xuất và đăng tải 01 Tiktok Video Review sản phẩm tại điểm bán Five Star Kiosk, theo định hướng nội dung của nhãn hàng - Thời lượng: 60-120s - Chất lượng: phù hợp điện thoại - Địa điểm: tại các Five Star Kiosk ở nơi sinh sống Map Five Star Kiosk: Link 01 tháng Sử dụng hình ảnh không độc quyền trên digital only *Bao gồm: Code Ads và reup kênh brand có chạy quảng cáo | I6: FALSE | J6: 11h00 sáng T6-15/5: Địa điểm quay: B8/28M Đường Hưng Nhơn, xã Tân Nhựt, huyện Bình Chánh | M6: Đã quay | N6: =Draft!M6 -> https://docs.google.com/spreadsheets/d/1vaRBTbnZy9dvsd-SpvXhO76Gg-InJKD2u8IGmvjbPTo/edit?gid=0#gid=0 | O6: =Draft!N6 | P6: Cảnh 2: - Chỉnh lại lời thoại — chi tiết “màu vàng huyền thoại của Five Star” chưa thật sự đúng vì màu nhận diện chính của Five Star là đỏ và vàng. - Thêm lời thoại theo hướng đi ngang nghe tiếng “xèo xèo” hoặc ngửi thấy mùi gà chiên quá hấp dẫn nên bị thu hút và quẹo vào mua, dù ban đầu chỉ định ghé mua nước. Cảnh 3: Chỉnh text - Gần 1000 điểm bán trên 30+ tỉnh thành Cảnh 4: - Chỉnh text - Menu siêu đa dạng Nhanh - Gọn - Ngon > mình ko nhấn mạnh về giá rẻ >> Note point này cho các bạn KOL luôn nha Cảnh 5: Câu thoại đầu chưa link rõ ràng tới đoạn sau > gợi ý có thể nói rõ là tại sao những món này lại phù hợp với người lười đợi từ đầu luôn. Gắn text thêm địa chỉ về địa điểm Five Star mà bạn đã ghé Overall ok có thể quay cận món nhiều hơn | Q6: =Draft!P6 -> https://docs.google.com/spreadsheets/d/1vaRBTbnZy9dvsd-SpvXhO76Gg-InJKD2u8IGmvjbPTo/edit?gid=1396100120#gid=1396100120 | R6: =Draft!Q6 -> Đã input thêm Outfit Team KOC đã điều chỉnh theo feedback của brand | S6: Do có thay đổi về địa chỉ review nên nhờ bạn thay bằng share link trong caption để mn có thể tìm các quán fivestar gần các bạn: https://fivestarnearyou.cp.com.vn/ ko cần add text địa chỉ lên clip nữa nhé mà chỉ kêu gọi vào link để tìm quán nha. | U6: https://drive.google.com/drive/folders/1WLes2-C3PZsK0zl4ZA5D5yJ1xAYDkhWR | V6: =Draft!U6 | W6: Gà tatsutaage /ta-chư-ta-gê/ > đọc chỉnh lại 0:23 - thay đoạn này bằng đoạn zoom in vô menu (như khúc sau) nếu còn source nha Leo's comment: 1. Đoạn 00:46 - Tên đúng "chả giò gai jor" | X6: https://drive.google.com/drive/folders/1WLes2-C3PZsK0zl4ZA5D5yJ1xAYDkhWR | Z6: Leo's comment: Phần sửa lồng vào sau nghe hơi miễn cưỡng. Còn lại ổn => VO sẽ đổi thành text add in | AA6: https://drive.google.com/file/d/1pmsQfzjtuZdATJQ_yn_7jK7w3fMZe-n8/view | AB6: Confirm | AD6: Gà chiên nóng hổi, cắn một miếng da giòn rụm, thịt bên trong vẫn mọng nước. #FiveStarVietnam #GaDau #FiveStar #GaRanFiveStar | AG6: 27/5 | AH6: https://www.tiktok.com/@lulureview_/video/7644513610072460551?_r=1&_t=ZS-96jI4dZLIL1
A7: 3 | B7: Hello Lập Đây | C7: Tiktok | D7: 260K | E7: Micro | F7: Link | G7: Hồ Chí Minh | H7: Sản xuất và đăng tải 01 Tiktok Video Review sản phẩm tại điểm bán Five Star Kiosk, theo định hướng nội dung của nhãn hàng - Thời lượng: 60-120s - Chất lượng: phù hợp điện thoại - Địa điểm: tại các Five Star Kiosk ở nơi sinh sống Map Five Star Kiosk: Link "01 tháng Sử dụng hình ảnh không độc quyền trên digital only *Bao gồm: Code Ads và reup kênh brand có chạy quảng cáo" | I7: TRUE | J7: Đã đi quay - 16h ngày 12/5 - OUTLET - HKD GÀ RÁN FIVE STAR THU HÀ - 37/3 Huỳnh Tấn Phát, Xã Nhà Bè, TPHCM | M7: Đã quay | N7: =Draft!M7 -> https://docs.google.com/spreadsheets/d/161njDQndXtRs8o07Zhz1nU0rtGGgw4RpJvwe5s0bWPc/edit?gid=0#gid=0 | O7: =Draft!N7 | P7: Trang phục: nhờ bạn chọn áo màu tươi hơn (đỏ hoặc vàng) Phân cảnh Body: - Đã đi ăn ngoài phải chọn ăn ngon > Sau câu này thêm 1 câu tại sao lại chọn Five Star > gợi ý: do gần nhà, do đi ngang qua thấy thèm, v.v. - Về giá > mình ko nhắc từ khóa rẻ hay mắc > chỉnh lại theo hướng phần ăn đầy đặn / xịn so với mức giá hoặc sử dụng các từ khóa như giá dễ chịu, ai cũng mua dc Cảnh outro: Câu còn lập thì có quan tâm ko > hơi bị khó hiểu Gắn text thêm địa chỉ về địa điểm Five Star mà bạn đã ghé | Q7: =Draft!P7 -> https://docs.google.com/spreadsheets/d/161njDQndXtRs8o07Zhz1nU0rtGGgw4RpJvwe5s0bWPc/edit?gid=972901149#gid=972901149 | R7: =Draft!Q7 -> Team KOC đã review nội dung và thay đổi outfit tươi hơn Hiện đang thiêu Địa chỉ cụ thể. team sẽ input sau | S7: Remove từ kiosk Ko cần add địa chỉ lên video > đổi thành share link website sang phần comment | U7: Demo Hello Lập Đây.mp4 | V7: =Draft!U7 | W7: 1:11 - zoom in hoặc là thay cảnh > để ko thấy rõ cái dây điện với đống bụi ở trên tường vì khúc đó mình đang nói về việc sạch sẽ 1:24 - Text trên clip - "Tập đoàn C.P. đến từ Thái Lan" ko phải là "tập đoàn C.P. Thái Lan" | X7: Revised R1.mp4 | Z7: Phần feedback sau sẽ được gom để xử lý ở demo R2 Leo's comment: 1. 00:24 - liệt kê các món xiên que: "Cá viên, bò viên, chả cá..." đổi thành "cá viên, bò viên, xúc xích phô mai.. đặc biệt còn có chả giò kiểu thái (or) chả giò gai jor" nghe có signature hơn là chỉ liệt kê những món bình thường 2. 00:36 - remove cảnh + thoại "khách đông cỡ này luôn" - cảnh thật chưa đủ đông, nghe hơi miễn cưỡng. 3. Đoạn 01:12 - "cửa hàng sạch sẻ" nên đổi cảnh quay cửa hàng, đang lồng trên cảnh staff chế biến gà, không match phần hình và phần tiếng. | AA7: Five star (fix 3).mp4 | AB7: Confirm | AD7: CAPTION: Brand gà rán này xứng đáng viral hơn gấp 10 lần | AE7: Chỉnh lại Brand gà rán > Thương hiệu / Brand thức ăn nhanh | AF7: Thương hiệu gà rán này xứng đáng viral hơn gấp 10 lần #hellolapday #FiveStarVietnam #GaDau #FiveStar #GaRanFiveStar | AG7: 46059 | AH7: - tiktok: https://vt.tiktok.com/ZSxt8cXaM/ - reup insta: https://www.instagram.com/reel/DY9hZnczdim/?igsh=MWk3cnVvcjlwZ3VndA==
A8: 4 | B8: Huyền Nhi | C8: Tiktok | D8: 118.1K | E8: Micro | F8: Link | G8: Hồ Chí Minh | H8: Sản xuất và đăng tải 01 Tiktok Video Review sản phẩm tại điểm bán Five Star Kiosk, theo định hướng nội dung của nhãn hàng - Thời lượng: 60-120s - Chất lượng: phù hợp điện thoại - Địa điểm: tại các Five Star Kiosk ở nơi sinh sống Map Five Star Kiosk: Link "01 tháng Sử dụng hình ảnh không độc quyền trên digital only *Bao gồm: Code Ads và reup kênh brand có chạy quảng cáo" | I8: TRUE | J8: 11h00 t7 16/5 quay, ĐỊa điểm: BASIC SHOP - Nguyễn Thị Thuận - Số 67 Đường 9, phường Trường Thọ, TP. Thủ Đức, TP. HCM | M8: Đã quay | N8: =Draft!M8 -> https://docs.google.com/spreadsheets/d/1TlMiQyjUC_8vG--FMqD48heIruNjrv0a_-BycV6vMug/edit?gid=2103508750#gid=2103508750 | O8: =Draft!N8 | P8: Trang phục ok Tập đoàn CP Group > Bỏ chữ Group Bổ sung thêm ý về việc an tâm về chất lượng và an toàn thực phẩm Bỏ đoạn "mà ko thấy áp lực chi phí" - Add thêm địa chỉ Five Star | Q8: https://docs.google.com/spreadsheets/d/1TlMiQyjUC_8vG--FMqD48heIruNjrv0a_-BycV6vMug/edit?gid=80012582#gid=80012582 | R8: Đã input thêm Outfit Team KOC đã điều chỉnh theo feedback của brand | S8: Remove từ kiosk Remove địa chỉ > add website tìm quán ở comment Còn lại ok | U8: https://drive.google.com/file/d/1BQQEQ3ggRs06IXWejYz58QsoKTgGPsd1/view | V8: =Draft!U8 | W8: 0:03: chỉnh text theo hướng - Five Star - Thế giới ăn vặt, thiên đường ăn no có món gà rán siêu đỉnh > highlight về sự đa dạng và món gà rán signature 0:27 > hình món khoai tây chiên hơi thường > đẩy món gà rán lên, có các món khác thì mình cho lên nha - Có mấy góc bạn cầm đĩa gà hình như bị lặp lại 2-3 lần trong clip, mình còn góc khác thì thay giúp chị nha Các món xiên que > khi liệt kê add 1 món signature chả giò gai jor (trong đĩa bạn có order) > gọi tên món thay vì chỉ gọi là xiên que thông thường Text: Đa dạng các loại xiêu que > chỉnh chút theo hướng "Menu xiên que đa dạng với nhiều món ngon lạ miệng" 1:00 - hot dog tên món là "hot dog Torpedo" 1:05 - remove cảnh bàn trống có 1 ng ngồi Nên add CTA kêu gọi ghé quán > địa chỉ nằm ở link | X8: https://drive.google.com/file/d/1FHJD-DVN5yvqkgqVIHgOR6tfsrWjR9ht/view?usp=drivesdk | Y8: =Draft!X8 | Z8: Chỉnh text: Tập đoàn C.P. Việt Nam 0:26 - highlight món gà nugget ngôi sao Còn lại ok | AA8: https://drive.google.com/file/d/1qJxaezCXrSlDXG29sDkksX_jZKoB9ZqM/view?usp=drivesdk | AB8: Confirm | AD8: Fan gà rán thì lưu ngay quán Five Star nha mọi người ơii, có thêm đồ ăn vặt và các món ăn no nữa nè #FiveStarVietnam #GaDau #FiveStar #GaRanFiveStar | AG8: 29/5 | AH8: https://www.tiktok.com/@hhuyennhiii/video/7644779715093482772?_r=1&_t=ZS-96jFcDqShi1
A9: 5 | B9: Thư Bonny | C9: Tiktok | D9: 114.7K | E9: Micro | F9: Link | G9: Hồ Chí Minh | H9: Sản xuất và đăng tải 01 Tiktok Video Review sản phẩm tại điểm bán Five Star Kiosk, theo định hướng nội dung của nhãn hàng - Thời lượng: 60-120s - Chất lượng: phù hợp điện thoại - Địa điểm: tại các Five Star Kiosk ở nơi sinh sống Map Five Star Kiosk: Link "01 tháng Sử dụng hình ảnh không độc quyền trên digital only *Bao gồm: Code Ads và reup kênh brand có chạy quảng cáo" | I9: TRUE | J9: Đã đi quay Lịch quay: 10h 12/5 Địa điểm: BASIC SHOP - Nguyễn Thị Thuận - Số 67 Đường 9, phường Trường Thọ, TP. Thủ Đức, TP. HCM | M9: Đã quay | N9: =Draft!M9 -> https://docs.google.com/spreadsheets/d/11qQ5wa_wLzoqxwxYWqwWOeh0TAKOK7_d4tXx9pgrw0M/edit?gid=0#gid=0 | O9: =Draft!N9 | P9: - Highlight thêm về sự tiện lợi, giá dễ chịu / khẩu phần đầy đặn so với mức giá / ai cũng có thể thưởng thức - Gắn thêm địa chỉ về địa điểm Five Star mà bạn đã ghé và thêm CTA | Q9: =Draft!P9 -> https://docs.google.com/spreadsheets/d/11qQ5wa_wLzoqxwxYWqwWOeh0TAKOK7_d4tXx9pgrw0M/edit?gid=1343518029#gid=1343518029 | R9: =Draft!Q9 -> Đã add thêm outfit KOC NOTE: chi tiết khẩu phần. mức giá thì sau khi trải nghiệm KOC mới có cơ sở để đánh giá nên sẽ tinh chỉnh kịch bản sau KOC đã thêm địa chỉ và CTA vào script | S9: Script ok Do có thay đổi về địa chỉ review nên nhờ bạn thay bằng share link trong caption để mn có thể tìm các quán fivestar gần các bạn: https://fivestarnearyou.cp.com.vn/ ko cần add text địa chỉ lên clip nữa nhé mà chỉ kêu gọi vào link để tìm quán nha. | U9: Demo Five Star - Thư Bonny | V9: =Draft!U9 | W9: Mình remove đoạn bạn nói order về nhà thì ok hơn (1:51-1:52) Leo's comment: 1. Clip có quá nhiều tạp âm, khó giữ người xem hết 2. Remove 01:12 - 01:22, màu xiên gà hơi tối, nhìn không đủ hấp dẫn, cũng khó hình dung là món gì. 3. 01:35 - Bổ sung "đùi góc tư tẩm ướp" | X9: https://drive.google.com/file/d/1QjurRtSs_004WtM0egChyuALFNen9LNO/view?usp=drivesdk | Y9: =Draft!X9 | Z9: Vẫn còn tạp âm > tiếng xe to Nhi's comment Nên mention thêm đến giá cả của FS ví dụ "Giá cả hợp lý" Còn lại ok | AA9: https://drive.google.com/file/d/1OyIKU1LjE8w9vI3IK6QMT15pNHB9X5v3/view?usp=drivesdk | AB9: Confirm | AD9: Nhớ tới hương vị của Five Star là phải đi ăn NGAY VÀ LUÔN #FiveStarVietnam #GaDau #FiveStar #GaRanFiveStar | AE9: có thể chỉnh theo hướng nhớ là phải đi liền ko Leo's comment: Cả clip vẫn còn tạp âm (tiếng xe, tiếng gà gáy..) 0:41: Tiếng xe to hơn tiếng nhai da gà. Hình ảnh ổn, trừ âm thanh => Cố gắng fix âm thanh | AF9: "Nhớ tới hương vị của Five Star là phải đi ăn NGAY VÀ LUÔN #FiveStarVietnam #GaDau #FiveStar #GaRanFiveStar " | AG9: 46059 | AH9: https://www.tiktok.com/@thubonny/video/7646757218007715079?_r=1&_t=ZS-96sF5iS0M78
A10: 6 | B10: Nuchuu nè | C10: Tiktok | D10: 756K | E10: Micro | F10: Link | G10: Hồ Chí Minh | H10: Sản xuất và đăng tải 01 Tiktok Video Review sản phẩm tại điểm bán Five Star Kiosk, theo định hướng nội dung của nhãn hàng - Thời lượng: 60-120s - Chất lượng: phù hợp điện thoại - Địa điểm: tại các Five Star Kiosk ở nơi sinh sống Map Five Star Kiosk: Link "01 tháng Sử dụng hình ảnh không độc quyền trên digital only *Bao gồm: Code Ads và reup kênh brand có chạy quảng cáo" | I10: FALSE | J10: - 15-17h ngày 13/5 - PREAMIUM KIOSK 3*3 - HKD FIVE STAR ĐINH ĐỨC THIỆN - 1/26 Đinh Đức Thiện, xã Bình Chánh, TP HCM | M10: Đã quay | N10: =Draft!M10 -> https://docs.google.com/spreadsheets/d/1SNimKtZBUz4pm9ejeDfbgV1a815ex8d26sGSutaoT0A/edit?gid=0#gid=0 | O10: =Draft!N10 | P10: - Nhờ bạn chọn áo nào màu tươi hơn, năng động hơn nhe - Bên cạnh mùi vị tuổi thơ > add thêm những câu nhận xét là so với ký ức tuổi thơ thì Five Star có gì mới hơn (ví dụ store nhìn chuẩn chỉnh hơn, chuyên nghiệp hơn, món ăn đa dạng hơn, v.v) - Ko nhắc tới từ khóa "rẻ" > thay bằng giá dễ chịu, giá hợp lý, khẩu phần chất lượng hơn so với giá - Gắn thêm địa chỉ về địa điểm Five Star mà bạn đã ghé | Q10: =Draft!P10 -> https://docs.google.com/spreadsheets/d/1SNimKtZBUz4pm9ejeDfbgV1a815ex8d26sGSutaoT0A/edit?gid=1256513125#gid=1256513125 | R10: =Draft!Q10 -> Hiện team KOC đã update nội dung nhưng thiếu địa chỉ cụ thể Đã thay đổi option outfit chờ team check | S10: Script ok nhé, thay chữ kiosk bằng "quán" giúp chị nha. Do có thay đổi về địa chỉ review nên nhờ bạn thay bằng share link trong caption để mn có thể tìm các quán fivestar gần các bạn: https://fivestarnearyou.cp.com.vn/ ko cần add text địa chỉ lên clip nữa nhé mà chỉ kêu gọi vào link để tìm quán nha. | U10: Fivestar.mov | W10: Màu sắc món > tươi hơn, tăng saturation 0:39 - có thể kéo dài đoạn đổ sốt một chút ko 1:19 > remove đoạn chiên > dầu hơi nâu Sai chính tả "Chuẩn Chỉnh" Leo's comment: 1. Đoạn 00:59 - add sai tên món => Đổi lại tên món "Gà Nugget" + thoại: hình ngôi sao nhìn thú vị.. 2. Đoạn 01:31 - đổi "đám bạn" thành "nhóm bạn" | X10: FIVESTARFIX.mov | Z10: Ức gà - ko bị khô > đổi thành ức gà mọng nước juicy 0:43: "lười có xương" -> bỏ đoạn này | AA10: Fivestar | AB10: Confirm | AD10: CAPTION: Món ăn tuổi thơ của tôi | AG10: 28/5 | AH10: https://vt.tiktok.com/ZSx45rKrU/
A11: 7 | B11: Ăn ngon cùng Puu | C11: Tiktok | D11: 345.4K | E11: Micro | F11: Link | G11: Hồ Chí Minh | H11: Sản xuất và đăng tải 01 Tiktok Video Review sản phẩm tại điểm bán Five Star Kiosk, theo định hướng nội dung của nhãn hàng - Thời lượng: 60-120s - Chất lượng: phù hợp điện thoại - Địa điểm: tại các Five Star Kiosk ở nơi sinh sống Map Five Star Kiosk: Link | I11: TRUE | J11: Ăn Ngon Cùng Puu Quay ngày 15/5 - 13h00 MINI SHOP - Five Star Mega Q12 - Số 2 đường Trương Thị Hoa, KP 4A, Tân Thới Hiệp, TPHCM | M11: Đã quay | N11: =Draft!M11 -> https://docs.google.com/spreadsheets/d/1jC0a00h3FsNPkNZqCO8tCfHq8Ux2lS9cjcq9OYS5YDw/edit?gid=0#gid=0 | O11: =Draft!N11 | P11: - CP Group > đổi thành tập đoàn CP - Bổ sung thêm ý về sự đa dạng (nhiều món người lớn con nít đều ăn được, từ món ăn no tới món ăn vặt) - Thêm ý về việc ăn 1 mình hay ăn nhiều người đều siêu hợp - Gắn thêm địa chỉ về địa điểm Five Star mà bạn đã ghé | Q11: https://docs.google.com/spreadsheets/d/1jC0a00h3FsNPkNZqCO8tCfHq8Ux2lS9cjcq9OYS5YDw/edit?gid=1937930012#gid=1937930012 | R11: Đã update script và Outfit chờ team check | S11: Trang phục ok Script ok nhé Thêm CTA: "Xem Store gần nhất bên dưới phần comment" + Cmt link web | U11: https://drive.google.com/drive/folders/110dLNgTuRhRmD7fAW9mPfIvRAASVPXpA | V11: =Draft!U11 | W11: Khúc đầu gà bị ám xanh Bỏ địa chỉ chi tiết Gà tẩm ướt > đùi gà góc tư tẩm ướt Highlight một số xiên que lạ miệng hoặc đọc tên món chi tiết > chả giò gai jor, hotdog xúc xích phô mai tẩm khoai tây, v.v Đoạn cuối > chọn gà rán hay xiên que ở five star > Chọn | X11: https://drive.google.com/drive/folders/110dLNgTuRhRmD7fAW9mPfIvRAASVPXpA | Y11: =Draft!X11 | Z11: Thiếu CTA cuối clip | AA11: https://drive.google.com/drive/folders/110dLNgTuRhRmD7fAW9mPfIvRAASVPXpA | AD11: "Top 1 địa chỉ gà trong lòng Pu đó chính là Fivestar này nè cả nhà ơi #FiveStarVietnam #GaDau" | AE11: ok Leo: Top 1 địa chỉ gà rán trong lòng Pu đó chính là Fivestar này nè cả nhà ơi #FiveStarVietnam #GaDau #GaRan | AG11: 14/6
A12: 8 | B12: A dinosaur in the kitchen | C12: Tiktok | D12: 294.8K | E12: Micro | F12: https://www.tiktok.com/@phamtrang.2401 | G12: Hà Nội | H12: Sản xuất và đăng tải 01 Tiktok Video Review sản phẩm tại điểm bán Five Star Kiosk, theo định hướng nội dung của nhãn hàng - Thời lượng: 60-120s - Chất lượng: phù hợp điện thoại - Địa điểm: tại các Five Star Kiosk ở nơi sinh sống Map Five Star Kiosk: Link "01 tháng Sử dụng hình ảnh không độc quyền trên digital only *Bao gồm: Code Ads và reup kênh brand có chạy quảng cáo" | I12: TRUE | J12: Thứ 5 ngày 21/5 (11h trưa) địa điểm Ngãi Cầu | M12: Đã confirm lịch | N12: https://docs.google.com/spreadsheets/d/1z-HdLijlKbGSj5qe5SrB_0F34ISWgdy1XuSDOjDegrg/edit?gid=0#gid=0 | O12: =Draft!N12 | P12: Trang phục ok - Opening > chỉnh lại ko nhấn mạnh vào việc rẻ mà đổi thành giá dễ chịu, ko đau ví mà khẩu phần thì chất lượng - 7 Eleven k thuộc CP > remove - Chỉnh CP Group > Tập đoàn C.P. - Nội dung đang focus vào giá rẻ, giá mềm khá nhiều > chỉnh lại để tập trung vào sự tiện lợi, chất lượng món ăn | Q12: https://docs.google.com/spreadsheets/d/1z-HdLijlKbGSj5qe5SrB_0F34ISWgdy1XuSDOjDegrg/edit?gid=1633982349#gid=1633982349 | R12: Team đã update outfit + script | S12: Script ok Thêm CTA: "Xem Store gần nhất bên dưới phần comment" + Cmt link web | U12: https://drive.google.com/file/d/1QWiIeGyMi5lPxKIJ3cVXH9IjQi11wUNE/view?usp=drivesdk | V12: =Draft!U12 | W12: Đọc tên các món xiên que luôn nhé> chả giò gai jor, hotdog xúc xích phô mai tẩm khoai tây, v.v Phần má đùi > đùi góc tư tẩm tiêu | X12: https://drive.google.com/file/d/1a9cTmTDG8Q4oW3-jqPiq0IK9eus3n2ML/view?usp=drivesdk | Y12: =Draft!X12 | Z12: Chất lượng video thấp 1:06, màu miếng gà tươi hơn 0:36 - gà nugget ngôi sao > nếu ko add VO thì add text giúp c Leo's comment 1:03 - 1:08: Bỏ "Điểm thấy hơi tiếc là không có nhiều sauce đi kèm lắm" nội dung này sẽ làm hạn chế nhu cầu khách hàng. Có thể giữ idea "mua gà về rồi tự chế sauce ăn kèm" để mang tính sáng tạo | AA12: https://drive.google.com/file/d/1VYvbOQfbuMKOKGFAvVH6GgciZr8rN3NX/view?usp=drivesdk | AB12: Confirm | AD12: muốn ăn gà rán ngon, giá HSSV, đa dạng lựa chọn thì ghé Five Star | AE12: Đổi thành giá siêu hời / giá dễ tiếp cận | AF12: muốn ăn gà rán ngon, giá siêu hời, đa dạng lựa chọn thì ghé Five Star | AG12: 46362
A13: 9 | B13: Đi Ăn Chưa 🍪 | H13: Sản xuất và đăng tải 01 Tiktok Video Review sản phẩm tại điểm bán Five Star Kiosk, theo định hướng nội dung của nhãn hàng - Thời lượng: 60-120s - Chất lượng: phù hợp điện thoại - Địa điểm: tại các Five Star Kiosk ở nơi sinh sống Map Five Star Kiosk: Link "01 tháng Sử dụng hình ảnh không độc quyền trên digital only *Bao gồm: Code Ads và reup kênh brand có chạy quảng cáo" | I13: FALSE | J13: Ngày Quay: "20/5 (19h) 3) basic shop Thị Thắm: Viết Xuân - Hà Đông hà nội https://fivestarnearyou.cp.com.vn/?Longtitude=105.7684087&Latitude=20.9698673" | M13: Đã confirm lịch | N13: https://docs.google.com/spreadsheets/d/1qrkChaVikylLImYDjoO9c9LJguLywYjcZlrLUc7Q0hI/edit?gid=0#gid=0 | O13: =Draft!N12 | P13: Add thêm ý về chất lượng sản phẩm > tươi ngon, k bị bở, miếng nào chắc miếng đó, v.v | Q13: https://docs.google.com/spreadsheets/d/1qrkChaVikylLImYDjoO9c9LJguLywYjcZlrLUc7Q0hI/edit?gid=1924183939#gid=1924183939 | R13: =Draft!Q12 | S13: Trang phục ok Script ok nhé | U13: https://drive.google.com/file/d/1kQpIV8620mDHm-rlSMxU6fggdmfaQJjL/view?usp=drivesdk | V13: =Draft!U12 | W13: Đoạn đầu VO chưa match với scene Highlight thêm 1 số món xiên que như chả giò gai jor, hotdog xúc xích phô mai tẩm khoai tây, v.v. Cho màu các món tươi hơn | X13: https://drive.google.com/file/d/1z8o7htdhrZZ_rAseU7a6rqR9Js2gAuoM/view?usp=drivesdk | Y13: =Draft!X12 | Z13: 0:03: bị cắt mất địa chỉ 0:34: ""hotdog tẩm khoai tây"" -> sửa hotdog xúc xích phô mai tẩm khoai tây chỉnh thêm cho clip sáng chút - màu ok | AD13: cap:Five Star - địa điểm mà tui luôn ghé khi chưa biết ăn gì | AE13: ok | AG13: 13/6
A14: FOODY UGC | I14: FALSE | J14: =Draft!J14 | N14: =Draft!M14 | O14: =Draft!N14 | Q14: =Draft!P14 | R14: =Draft!Q14
A15: a | B15: TP HCM | I15: FALSE | J15: =Draft!J15 | N15: =Draft!M15 | O15: =Draft!N15 | Q15: =Draft!P15 | R15: =Draft!Q15
A16: 10 | B16: Nhà Mây | C16: Tiktok | D16: 187.9K | E16: Micro | F16: link | G16: Hồ Chí Minh | H16: Sản xuất và đăng tải 01 Tiktok Video Review sản phẩm tại điểm bán Five Star Kiosk, theo định hướng nội dung của nhãn hàng - Thời lượng: 60-120s - Chất lượng: phù hợp điện thoại - Địa điểm: tại các Five Star Kiosk ở nơi sinh sống Map Five Star Kiosk: Link "01 tháng Sử dụng hình ảnh không độc quyền trên digital only *Bao gồm: Code Ads và reup kênh brand có chạy quảng cáo" | I16: TRUE | J16: 16/05 - 16h00 Số 67 Đường 9, phường Trường Thọ, TP. Thủ Đức, TP. HCM | M16: Đã quay | N16: =Draft!M16 -> https://docs.google.com/spreadsheets/d/1xQ1mD1D5YIQbOnp-TcVfi31RHqUWCR8Z0vOrkp-JFkc/edit?gid=0#gid=0 | O16: =Draft!N16 | P16: - Bổ sung thêm context ở khúc đầu để rõ ý với tạo sự quen thuộc hơn > đón bé từ trường học về - Thêm góc nhìn của bé > ý kiến của bé về món ăn, reaction khi ăn > bé yêu thích như thế nào - Có thể bổ sung thêm yếu tố đa dạng, nhiều món từ ăn no tới ăn vặt - CTA chưa hấp dẫn> có thể chỉnh theo hướng "Muốn ăn nhanh, tiện mà vẫn ngon miệng thì Five Star là một option khá đáng thử" hoặc là "Hôm nào muốn đổi bữa cho đỡ ngán cơm nhà mà ko phải đi xa, thử dẫn bé ghé Five Star ăn nhanh một bữa nóng giòn nhé!" | Q16: https://docs.google.com/spreadsheets/d/1xQ1mD1D5YIQbOnp-TcVfi31RHqUWCR8Z0vOrkp-JFkc/edit?gid=1550874505#gid=1550874505 | R16: Đã update script và Outfit chờ team check | S16: Remove từ kiosk Remove từ "rẻ" Ko cần gắn địa chỉ lên video, add website CH fivestarnearyou.cp.com.vn ở phần comment | U16: https://drive.google.com/file/d/1x8QOtbLWnADBcJywmLn0W5ait-HDHlKo/view | V16: =Draft!U16 | W16: Frame 1 chưa theo sát script Remove đoạn dưới 300k > ko nhắc về giá rẻ Remove địa chỉ cuối clip > kêu gọi tới website Add text / hoặc thêm review ngắn các món xiên que, nêu tên cụ thể như hotdog xúc xích phô mai tẩm khoai tây, chả giò gai jor, gà nugget ngôi sao Màu clip tổng thể hơi tối > cho sáng lên | X16: https://drive.google.com/file/d/1keeYRqLAubhlGzyjqcHeWfszahdAURLY/view?usp=sharing | Y16: =Draft!X16 | Z16: Frame 1 chưa theo sát script 0:20 - cho clip chậm lại chút để đọc text CTA thêm ghé tiệm five star gần nhà Leo's comment: 0:16 - 0:18: Màu dầu hơi tối, chỉnh màu sáng hơn (trong trường hợp chỉnh sáng không được thì remove đoạn này) 0:40: Thoại của nhân vật con gái nói nhanh và âm thanh hơi chói, khó nghe. Nói chậm và rõ ý lại | AA16: Five Star.mp4 | AB16: Đã revise text pop up -> Confirm | AD16: "Món yêu thích của e bé nhà Mây là gà Fivestar đó cả nhà ơi #FiveStarVietnam #GaDau" | AE16: ok Leo: Hashtag - #FiveStarVietnam #GaDau #GaRan | AG16: 46271
A17: 11 | B17: Đi chill cùng Phương phiêu | C17: Tiktok | D17: 57.7K | E17: Nano | F17: link | G17: Hồ Chí Minh | H17: Sản xuất và đăng tải 01 Tiktok Video Review sản phẩm tại điểm bán Five Star Kiosk, theo định hướng nội dung của nhãn hàng - Thời lượng: 60-120s - Chất lượng: phù hợp điện thoại - Địa điểm: tại các Five Star Kiosk ở nơi sinh sống Map Five Star Kiosk: Link "01 tháng Sử dụng hình ảnh không độc quyền trên digital only *Bao gồm: Code Ads và reup kênh brand có chạy quảng cáo" | I17: FALSE | J17: 17h thứ 2 18/2 HN nha "Ngãi cầu Hà Nội | N17: =Draft!M17 -> https://docs.google.com/spreadsheets/d/1fpgklNz15kb8DM2y7cMvWmIrrpZJ52PQO1AcoqBHmEA/edit?gid=0#gid=0 | O17: =Draft!N17 | P17: - Review thêm hương vị các món xiên que (nóng hổi, thơm ngon, v.v.) - Add thêm tiếng cắn gà / tiếng ăn các món cho thêm hấp dẫn - Add thêm địa chỉ Five Star | Q17: https://docs.google.com/spreadsheets/d/1fpgklNz15kb8DM2y7cMvWmIrrpZJ52PQO1AcoqBHmEA/edit?gid=335140389#gid=335140389 | R17: Đã update script và Outfit chờ team check | S17: Trang phục ok Script ok Thêm CTA: "Xem Store gần nhất bên dưới phần comment" + Cmt link web | U17: https://drive.google.com/file/d/1Vo1WLNbMtD_wKSf6FcK2245x0oUL2Au6/view?usp=drivesdk | V17: =Draft!U17 | W17: 0:22 - giấy trên bàn > làm mờ đi vì làm hình tổng thể ko đẹp mắt Màu sắc đồ ăn cho tươi hơn, sáng hơn liệt kê các món xiên que > sử dụng đúng tên món như chả giò gai jor, hotdog xúc xích phô mai, v.v. Leo's comment: Mở bài hơi dài, tốn 18 giây (chiếm 38%) thời lượng clip => Cắt ngắn lại, giới thiệu về brand, về sản phẩm nhiều hơn 0:20 - 0:30: Nên thêm text tên món | X17: https://drive.google.com/file/d/1eF6shCgyyvjXuLPZACynSS5SwkfR5qDC/view?usp=drivesdk | Y17: =Draft!X17 | Z17: Thiếu CTA cuối clip 0:11 - clip hơi mờ > làm cho nét sharpen, rõ hơn 0:22 - sai tên món > đùi gà góc tư Leo's commet: 0:18: Vẫn còn "K" phải đợi | AD17: "Tan ca mà lười nấu ăn, thì Phương hay đến Fivestar để ăn nè. Nhanh tiện, mà giá cả quá ư là hợp lí nữa! #FiveStarVietnam #GaDau" | AE17: Caption ko hấp dẫn, chưa highlight dc vị ngon / điểm làm FS đặc biệt > nhanh, tiện, hợp vệ sinh là điều cơ bản hệ thống fastfood nào cũng phải có | AF17: """Tan ca mà lười nấu ăn, thì Phương hay đến Fivestar để ăn nè. Nhanh tiện, mà giá cả quá ư là hợp lí nữa! #FiveStarVietnam #GaDau""" | AG17: 46332
A18: 12 | B18: 🍊𝐕 𝐈 𝐓 𝐀 𝐌 𝐈 𝐍 𝐂🍊 | C18: Tiktok | D18: 10.1K | E18: Nano | F18: link | G18: Hồ Chí Minh | H18: Sản xuất và đăng tải 01 Tiktok Video Review sản phẩm tại điểm bán Five Star Kiosk, theo định hướng nội dung của nhãn hàng - Thời lượng: 60-120s - Chất lượng: phù hợp điện thoại - Địa điểm: tại các Five Star Kiosk ở nơi sinh sống Map Five Star Kiosk: Link "01 tháng Sử dụng hình ảnh không độc quyền trên digital only *Bao gồm: Code Ads và reup kênh brand có chạy quảng cáo" | I18: FALSE | J18: 14/5 - 12h00 PREAMIUM KIOSK 4*3 - HKD PHAN TẤN TÀI - 223 Ấp 2, xã Bình Chánh, TP HCM | M18: Đã quay | N18: =Draft!M18 -> https://docs.google.com/spreadsheets/d/1Zs-sbAumg9ydXNKSreenvInyRfXK3lg9oVTB-V7R3bY/edit?gid=0#gid=0 | O18: =Draft!N18 | P18: - Thay vì rủ bạn NV chính đi bằng cách nói đi cái này hay nè > chỉnh thành hướng tạo cảm giác “Five Star là chỗ quen thuộc nhưng lúc nào cũng thấy thích ghé”, để tăng sự yêu thích và cảm giác đặc biệt hơn với brand. Ví dụ như : “Đi Five Star hông, lâu rồi chưa ăn lại mà tự nhiên nhớ.”, “Không biết ăn gì là auto nghĩ tới Five Star luôn á.”, “Em biết chỗ này nè, mỗi lần bí kèo ăn là lại muốn ghé.” - Review thêm về độ phủ của Five Star (ở nhiều nơi, nhất là mấy khu dân cư / trường học > tùy theo quan sát của bạn KOC) - Review thêm hương vị của các món xiên que hoặc về độ nóng, độ giòn, độ juicy / dai ngon ăn kèm sốt thì ntn - Add thêm địa chỉ Five Star | Q18: https://docs.google.com/spreadsheets/d/1Zs-sbAumg9ydXNKSreenvInyRfXK3lg9oVTB-V7R3bY/edit?gid=137961595#gid=137961595 | R18: Đã update script và Outfit chờ team check | S18: Trang phục chọn màu sắc tươi năng động hơn Remove từ kiosk Còn lại ok Thêm CTA: "Xem Store gần nhất bên dưới phần comment" + Cmt link web | U18: https://drive.google.com/drive/folders/15ODXPBRTw5WmN8MAY5ueU-3G_tHaar-8 | V18: =Draft!U18 | W18: Bỏ địa chỉ Xiên que, highlight text thêm các món đặc biệt / lạ như chả giò gai jor (bạn nữ có ăn) 0:41, hotdog xúc xích phô mai tẩm khoai tây 0:43 Đoạn show đồ ăn 0:30s trở đi > cho màu sắc tươi hơn và sáng hơn | X18: https://drive.google.com/file/d/18El277CcGBgrfq_x9z3o9IyPtWrXKCY4/view?usp=drivesdk | Y18: =Draft!X18 | Z18: Leo's comment: 0:45: "Phần da tẩm vị hơi đậm" nghe như là chê mặn hơn là khen sự đậm đà => Đổi "Phần da tẩm vị đậm đà" | AA18: https://drive.google.com/file/d/126XMma-dkzPcV3-Uut9x2qxhXLqiFHIR/view?usp=drivesdk | AB18: Confirm (Add CTA / share địa chỉ Five Star) | AD18: "Mấy ngày công việc nhiều, không biết ăn gì thì Fivestar là món ngon mà 2 vợ chồng mình chọn #FiveStarVietnam #GaDau" | AE18: Leo: Ok | AG18: 46271
A19: 13 | B19: Chu Cao Food | C19: Tiktok | D19: 67.4K | E19: Nano | F19: Link | G19: Hồ Chí Minh | H19: Sản xuất và đăng tải 01 Tiktok Video Review sản phẩm tại điểm bán Five Star Kiosk, theo định hướng nội dung của nhãn hàng - Thời lượng: 60-120s - Chất lượng: phù hợp điện thoại - Địa điểm: tại các Five Star Kiosk ở nơi sinh sống Map Five Star Kiosk: Link "01 tháng Sử dụng hình ảnh không độc quyền trên digital only *Bao gồm: Code Ads và reup kênh brand có chạy quảng cáo" | I19: FALSE | J19: T2 18/05 15h BASIC SHOP - Nguyễn Thị Thuận - Số 67 Đường 9, phường Trường Thọ, TP. Thủ Đức, TP. HCM | M19: Đã confirm lịch | N19: =Draft!M19 -> https://docs.google.com/spreadsheets/d/191E4WQVYqKQGCKUc6VNpr6XcIAnFaPVzZakBmOWs_dE/edit?gid=0#gid=0 | O19: =Draft!N19 | P19: - Khi nói về mọng nước, có thể quay cận cảnh miếng gà - Nên có khúc trả lời cho câu "Hôm nay mình ăn thử lại xem còn ngon như trong trí nhớ không nha." - Add thêm địa chỉ Five Star | Q19: https://docs.google.com/spreadsheets/d/191E4WQVYqKQGCKUc6VNpr6XcIAnFaPVzZakBmOWs_dE/edit?gid=476608211#gid=476608211 | S19: Remove từ Kiosk Còn lại ok, Thêm CTA: "Xem Store gần nhất bên dưới phần comment" + Cmt link web | U19: https://drive.google.com/drive/folders/10RsGeU0svEawSYop60YVJ8WO2n4-KhtB | V19: =Draft!U19 | W19: - Đoạn đầu đang khác script "" kiểu đang không biết ăn gì mà cứ đi ngang thấy Five Star là tự động tấp vô"" - Âm thanh đang chưa ổn định, lúc to lúc nhỏ - Có thể treat text theo kiểu khác thay vì pop up từng chữ "- Ko để địa chỉ, chỉ share phần link địa chỉ ở comment - Giọng VO khó nghe, như có tiếng ồn giọng hơi nghẹt - Cho tiếng rán to hơn 1:20 - tên món là: HOTDOG XÚC XÍCH PHÔ MAI TẨM KHOAI TÂY" Nhi's comment: - 1:59: sai lỗi chính tả "recommend" - Voice chưa trôi chảy, nhiều từ "kiểu như là", à ờ hơi nhiều Leo's comment: - Nguyên video chỗ nào có hiệu ứng text bay phấp phới thì bỏ hết - 00:22: Bỏ "đông đông vui vui" cảnh trước vắng cảnh sau nói đông vui không khớp - 00:28: Bỏ source nhún nhảy + vuốt tóc bấm điện thoại, giữ thông tin chờ món nhanh ... thay bằng source hình khác - 00:34: Nghe tiếng xèo xèo nên đi kèm với source chiên gà. Thích lớp da vàng giòn nên đi kèm với source cầm miếng gà. Hiện tại tiếng và hình đang lệch nhau (cảm giác tiếng đi trước, hình theo sau) - 00:41: Giọng nghẹt nghe không rõ, "không có bị khô" dễ nghe thành "không có bị hôi" => fix âm thanh - 00:43: Nhìn "miếng gà thấy tan trong miệng luôn" nghe kì, không tạo cảm giác giòn, đổi thành "nhìn miếng gà màu vàng ươm sau khi mới chiên, cảm giác sẽ giòn rụm khi nhai luôn á" - 00:53: "Ở đây là một cái thức ăn nhanh, ăn xong thấy khá chất lượng luôn" > chỉnh lại "Đây là chuỗi thức ăn nhanh có gà rán và nhiều món nữa, mà nãy giờ ăn tui thấy chất lượng khá là tốt luôn" - 01:03: Remove source cầm dĩa gà khá trống nhưng lại nói đầy đặn, nghe hơi miễn cưỡng. "Giá phù hợp cho một (phần/người)? => Edit lỗi, fix. - 02:01: Bỏ "ăn mấy món này về tập thể dục đã luôn" - 02:09: Bỏ " FS lúc nào cũng có người đứng ăn". Bỏ "tiêu chí thứ nhất" vì sau khi liệt kê cũng không có thêm tiêu chí 2 và 3 nên không cần thiết | X19: FIVE STAR - Chu Cao Food | Z19: Tiếng hơi lớn hơi bị ồm 0:33 & 1:27 - lúc bạn nói chưa match với VO | AA19: https://drive.google.com/file/d/1Ee_jefL9ivLqDX_6vK1glOjjKN7Q7wHX/view?usp=drivesdk | AB19: Nhiều chỗ VO ko khớp > có thể thay scene cho phù hợp Giảm bớt độ lớn của VO Leo's comment: Tiếng hơi rè, không khớp hình. 0:30 - 0:36 nói cái gì không hiểu, lặp từ "đặc biệt", "bị hôi" là sao? 1:02 - 1:05 "chả cá hàn quốc, dog, xúc xích đức, hô mai..." ???? Không thể hiểu được đang lồng nội dung gì | AD19: Nếu hôm nay chưa biết ăn gì thì thử tự thưởng cho mình 1 phần gà Five Star nha 😭🍗 #FiveStarVietnam #GaDau | AE19: Có clip chưa ha? Về caption - Five Star ko chỉ có gà > highlight là Gà & các món ăn vặt - ăn no | AF19: "Tui muốn ăn gà, mà người iu tui muốn ăn xiên que. Hổng sợ tranh nhau nữa vì tui đã có Fivestar, đa dạng món ăn mà ngon bổ rẻ #FiveStarVietnam #GaDau" | AG19: 46179
A20: 14 | B20: Hi Ân nè | C20: Tiktok | D20: 6489 | E20: Nano | F20: link | G20: Hồ Chí Minh | H20: Sản xuất và đăng tải 01 Tiktok Video Review sản phẩm tại điểm bán Five Star Kiosk, theo định hướng nội dung của nhãn hàng - Thời lượng: 60-120s - Chất lượng: phù hợp điện thoại - Địa điểm: tại các Five Star Kiosk ở nơi sinh sống Map Five Star Kiosk: Link "01 tháng Sử dụng hình ảnh không độc quyền trên digital only *Bao gồm: Code Ads và reup kênh brand có chạy quảng cáo" | I20: FALSE | J20: 13h00 15/5, thứ 6 BASIC SHOP - Nguyễn Thị Thuận - Số 67 Đường 9, phường Trường Thọ, TP. Thủ Đức, TP. HCM | M20: Đã quay | N20: =Draft!M20 -> https://docs.google.com/spreadsheets/d/14zMYJFq84bLogXppl5iBijvsYFm90xU8MuxJDdbrRZ4/edit?gid=0#gid=0 | O20: =Draft!N20 | P20: - Bổ sung thêm context hoặc cảm xúc cá nhân / đặc điểm unique mà bạn thấy Fivestar có mà chỗ khác chưa có để tạo sự khác biệt, gần gũi và đáng nhớ cho ng xem hơn | Q20: https://docs.google.com/spreadsheets/d/14zMYJFq84bLogXppl5iBijvsYFm90xU8MuxJDdbrRZ4/edit?gid=1983410445#gid=1983410445 | S20: Thêm CTA: "Xem Store gần nhất bên dưới phần comment" + Cmt link web Script và trang phục ok | U20: https://drive.google.com/file/d/19qrXjrJe-qlyzar7iRfiheO-QPwlJR4O/view?usp=drive_link | V20: =Draft!U20 | W20: Màu các món hơi tối, chưa dc tươi Bỏ chỉ có 9k, chỉ có 10k, chưa tới 300 > ko highlight việc rẻ, có thể nói giá hời (theo script) Five star chicken > remove chữ chicken, font chữ đang để shading đen làm che món ăn Remove địa chỉ | X20: https://drive.google.com/file/d/18J0RawbXOkA9mYVVANfpCAohF9Hrz5TD/view?usp=drivesdk | Y20: =Draft!X20 | Z20: 0:39 - 0:43: nói tên các món xiên que + chèn thêm text Leo's comment: 0:32 - 0:33: Remove, nhìn phần thịt và xương không đủ juicy, không tạo cảm giác mềm mọng | AA20: https://drive.google.com/file/d/1F0SA7JeRx1EqdmlRkFGSBF_SaabxMNu8/view?usp=drivesdk | AB20: Confirm | AD20: Mỗi lần thèm đồ chiên là trong đầu chỉ hiện lên Five Star thôi á 🍗✨ #FiveStarVietnam #GaDau | AE20: Ok | AG20: 46118 | AH20: https://vt.tiktok.com/ZSQJJgvLk/
A21: 15 | B21: vuvicungyuhi | C21: Tiktok | D21: 82.9K | E21: Nano | F21: https://www.tiktok.com/@vuvicungyuhi | G21: Hồ Chí Minh | H21: Sản xuất và đăng tải 01 Tiktok Video Review sản phẩm tại điểm bán Five Star Kiosk, theo định hướng nội dung của nhãn hàng - Thời lượng: 60-120s - Chất lượng: phù hợp điện thoại - Địa điểm: tại các Five Star Kiosk ở nơi sinh sống Map Five Star Kiosk: Link "01 tháng Sử dụng hình ảnh không độc quyền trên digital only *Bao gồm: Code Ads và reup kênh brand có chạy quảng cáo" | I21: FALSE | J21: Thời gian: 13/5 - 11h00 7. OUTLET - HKD GÀ RÁN FIVE STAR THU HÀ - 37/3 Huỳnh Tấn Phát, Xã Nhà Bè, TPHCM | M21: Đã quay | N21: https://docs.google.com/spreadsheets/d/1hY2b8b5_EtKYxGXaNgirKjOArXXbMdXlIgAe3-7WkNw/edit?gid=0#gid=0 | O21: =Draft!N21 | P21: Trang phục năng động hơn, màu tươi hơn - Idea opening về việc từng thấy kiosk Five Star ở Thái ok, - Đoạn nói về “gà rán Thái Lan” hơi chưa thực tế vì thực ra trải nghiệm khác biệt giữa Thái và Việt Nam chủ yếu nằm ở phần sốt/vị địa phương hóa hơn là bản thân món gà. - Đoạn “không biết ở Việt Nam cũng có Five Star” đang chưa tự nhiên và thiếu hợp lý. Có thể chỉnh theo hướng cảm giác bất ngờ vì gặp lại brand từng thấy ở VN ngay tại Thái Lan > nên giờ muốn thử để xem có giống vị ko. - Chỉnh lại "Five Star là thương hiệu thức ăn nhanh đến từ Thái Lan với hơn 5000 điểm bán, thuộc tập đoàn CP Việt Nam" > Five Star là thương hiệu thức ăn nhanh đến từ tập đoàn CP của Thái Lan với gần 1000 điểm bán. | Q21: https://docs.google.com/spreadsheets/d/1hY2b8b5_EtKYxGXaNgirKjOArXXbMdXlIgAe3-7WkNw/edit?gid=0#gid=0 | R21: Team đã update outfit + script | S21: "Remove từ khóa ""bình dân"" Còn lại ok Thêm CTA: "Xem Store gần nhất bên dưới phần comment" + Cmt link web | U21: https://drive.google.com/file/d/1wQIqstwbnbealKyyFsN0sumUkzSEeYAn/view?usp=drivesdk | V21: =Draft!U21 | W21: 0:51 - Remove keyword "Giá cả bình dân" hoặc thay bằng "giá cả hợp lý" Remove đoạn chỉ từ 10-25k luôn Khi liệt kê các món xiên que > bên cạnh bò viên, cá viên thì đặc biệt còn có các món chả giò Gai Jor, Chả cá hàn quốc chiên | X21: https://drive.google.com/file/d/1KeJ_kihAFCrhD7fNant8IKnYB43OjuCU/view?usp=drivesdk | Y21: =Draft!X21 | Z21: đoạn này bạn chưa sửa: chả giò Gai Jor, Chả cá hàn quốc chiên, xúc xích sumo Mấy đoạn bạn cầm hộp thức ăn màu bị lạnh, chưa tươi | AA21: https://drive.google.com/file/d/16bpYZ2ZbxWQPkEa828FQZyQTt6JkgZ9U/view?usp=drivesdk | AB21: Confirm | AD21: Thử gà rán Fivestar chưa mấy bà? | AE21: Ok | AG21: 46059 | AH21: https://www.tiktok.com/@vuvicungyuhi/video/7645645226396241160?is_from_webapp=1&sender_device=pc&web_id=7637478982196135431
